Traceback (most recent call last):
  File "/Users/jankirenz/opt/anaconda3/lib/python3.8/site-packages/jupyter_cache/executors/utils.py", line 51, in single_nb_execution
    executenb(
  File "/Users/jankirenz/opt/anaconda3/lib/python3.8/site-packages/nbclient/client.py", line 1112, in execute
    return NotebookClient(nb=nb, resources=resources, km=km, **kwargs).execute()
  File "/Users/jankirenz/opt/anaconda3/lib/python3.8/site-packages/nbclient/util.py", line 74, in wrapped
    return just_run(coro(*args, **kwargs))
  File "/Users/jankirenz/opt/anaconda3/lib/python3.8/site-packages/nbclient/util.py", line 53, in just_run
    return loop.run_until_complete(coro)
  File "/Users/jankirenz/opt/anaconda3/lib/python3.8/asyncio/base_events.py", line 616, in run_until_complete
    return future.result()
  File "/Users/jankirenz/opt/anaconda3/lib/python3.8/site-packages/nbclient/client.py", line 553, in async_execute
    await self.async_execute_cell(
  File "/Users/jankirenz/opt/anaconda3/lib/python3.8/site-packages/nbclient/client.py", line 857, in async_execute_cell
    self._check_raise_for_error(cell, exec_reply)
  File "/Users/jankirenz/opt/anaconda3/lib/python3.8/site-packages/nbclient/client.py", line 760, in _check_raise_for_error
    raise CellExecutionError.from_cell_and_msg(cell, exec_reply_content)
nbclient.exceptions.CellExecutionError: An error occurred while executing the following cell:
------------------
df['horsepower'] = pd.to_numeric(df['horsepower']) # produces error
------------------

[0;31m---------------------------------------------------------------------------[0m
[0;31mValueError[0m                                Traceback (most recent call last)
[0;32m~/opt/anaconda3/lib/python3.8/site-packages/pandas/_libs/lib.pyx[0m in [0;36mpandas._libs.lib.maybe_convert_numeric[0;34m()[0m

[0;31mValueError[0m: Unable to parse string "?"

During handling of the above exception, another exception occurred:

[0;31mValueError[0m                                Traceback (most recent call last)
[0;32m/var/folders/9c/_3s5jt3n60j__flsgl0t72340000gn/T/ipykernel_7138/2192086555.py[0m in [0;36m<module>[0;34m[0m
[0;32m----> 1[0;31m [0mdf[0m[0;34m[[0m[0;34m'horsepower'[0m[0;34m][0m [0;34m=[0m [0mpd[0m[0;34m.[0m[0mto_numeric[0m[0;34m([0m[0mdf[0m[0;34m[[0m[0;34m'horsepower'[0m[0;34m][0m[0;34m)[0m [0;31m# produces error[0m[0;34m[0m[0;34m[0m[0m
[0m
[0;32m~/opt/anaconda3/lib/python3.8/site-packages/pandas/core/tools/numeric.py[0m in [0;36mto_numeric[0;34m(arg, errors, downcast)[0m
[1;32m    181[0m         [0mcoerce_numeric[0m [0;34m=[0m [0merrors[0m [0;32mnot[0m [0;32min[0m [0;34m([0m[0;34m"ignore"[0m[0;34m,[0m [0;34m"raise"[0m[0;34m)[0m[0;34m[0m[0;34m[0m[0m
[1;32m    182[0m         [0;32mtry[0m[0;34m:[0m[0;34m[0m[0;34m[0m[0m
[0;32m--> 183[0;31m             values, _ = lib.maybe_convert_numeric(
[0m[1;32m    184[0m                 [0mvalues[0m[0;34m,[0m [0mset[0m[0;34m([0m[0;34m)[0m[0;34m,[0m [0mcoerce_numeric[0m[0;34m=[0m[0mcoerce_numeric[0m[0;34m[0m[0;34m[0m[0m
[1;32m    185[0m             )

[0;32m~/opt/anaconda3/lib/python3.8/site-packages/pandas/_libs/lib.pyx[0m in [0;36mpandas._libs.lib.maybe_convert_numeric[0;34m()[0m

[0;31mValueError[0m: Unable to parse string "?" at position 32
ValueError: Unable to parse string "?" at position 32

