Traceback (most recent call last):
  File "/Users/jankirenz/opt/anaconda3/lib/python3.7/site-packages/jupyter_cache/executors/utils.py", line 56, in single_nb_execution
    record_timing=False,
  File "/Users/jankirenz/opt/anaconda3/lib/python3.7/site-packages/nbclient/client.py", line 1112, in execute
    return NotebookClient(nb=nb, resources=resources, km=km, **kwargs).execute()
  File "/Users/jankirenz/opt/anaconda3/lib/python3.7/site-packages/nbclient/util.py", line 74, in wrapped
    return just_run(coro(*args, **kwargs))
  File "/Users/jankirenz/opt/anaconda3/lib/python3.7/site-packages/nbclient/util.py", line 53, in just_run
    return loop.run_until_complete(coro)
  File "/Users/jankirenz/opt/anaconda3/lib/python3.7/asyncio/base_events.py", line 587, in run_until_complete
    return future.result()
  File "/Users/jankirenz/opt/anaconda3/lib/python3.7/site-packages/nbclient/client.py", line 554, in async_execute
    cell, index, execution_count=self.code_cells_executed + 1
  File "/Users/jankirenz/opt/anaconda3/lib/python3.7/site-packages/nbclient/client.py", line 857, in async_execute_cell
    self._check_raise_for_error(cell, exec_reply)
  File "/Users/jankirenz/opt/anaconda3/lib/python3.7/site-packages/nbclient/client.py", line 760, in _check_raise_for_error
    raise CellExecutionError.from_cell_and_msg(cell, exec_reply_content)
nbclient.exceptions.CellExecutionError: An error occurred while executing the following cell:
------------------
%matplotlib inline

import pandas as pd
import numpy as np
import seaborn as sns 
import matplotlib.pyplot as plt

import tensorflow as tf
from tensorflow import keras
from tensorflow.keras import layers
from tensorflow.keras.layers.experimental import preprocessing

print(tf.__version__)

sns.set_theme(style="ticks", color_codes=True)
------------------

[0;31m---------------------------------------------------------------------------[0m
[0;31mImportError[0m                               Traceback (most recent call last)
[0;32m/var/folders/35/43bdsj9j64j16410rds5g9vr0000gp/T/ipykernel_49619/1262170889.py[0m in [0;36m<module>[0;34m[0m
[1;32m      9[0m [0;32mfrom[0m [0mtensorflow[0m [0;32mimport[0m [0mkeras[0m[0;34m[0m[0;34m[0m[0m
[1;32m     10[0m [0;32mfrom[0m [0mtensorflow[0m[0;34m.[0m[0mkeras[0m [0;32mimport[0m [0mlayers[0m[0;34m[0m[0;34m[0m[0m
[0;32m---> 11[0;31m [0;32mfrom[0m [0mtensorflow[0m[0;34m.[0m[0mkeras[0m[0;34m.[0m[0mlayers[0m[0;34m.[0m[0mexperimental[0m [0;32mimport[0m [0mpreprocessing[0m[0;34m[0m[0;34m[0m[0m
[0m[1;32m     12[0m [0;34m[0m[0m
[1;32m     13[0m [0mprint[0m[0;34m([0m[0mtf[0m[0;34m.[0m[0m__version__[0m[0;34m)[0m[0;34m[0m[0;34m[0m[0m

[0;31mImportError[0m: cannot import name 'preprocessing' from 'tensorflow.keras.layers.experimental' (/Users/jankirenz/opt/anaconda3/lib/python3.7/site-packages/tensorflow/python/keras/api/_v1/keras/layers/experimental/__init__.py)
ImportError: cannot import name 'preprocessing' from 'tensorflow.keras.layers.experimental' (/Users/jankirenz/opt/anaconda3/lib/python3.7/site-packages/tensorflow/python/keras/api/_v1/keras/layers/experimental/__init__.py)

