Traceback (most recent call last):
  File "/Users/jankirenz/opt/anaconda3/lib/python3.8/site-packages/jupyter_cache/executors/utils.py", line 51, in single_nb_execution
    executenb(
  File "/Users/jankirenz/opt/anaconda3/lib/python3.8/site-packages/nbclient/client.py", line 1112, in execute
    return NotebookClient(nb=nb, resources=resources, km=km, **kwargs).execute()
  File "/Users/jankirenz/opt/anaconda3/lib/python3.8/site-packages/nbclient/util.py", line 74, in wrapped
    return just_run(coro(*args, **kwargs))
  File "/Users/jankirenz/opt/anaconda3/lib/python3.8/site-packages/nbclient/util.py", line 53, in just_run
    return loop.run_until_complete(coro)
  File "/Users/jankirenz/opt/anaconda3/lib/python3.8/asyncio/base_events.py", line 616, in run_until_complete
    return future.result()
  File "/Users/jankirenz/opt/anaconda3/lib/python3.8/site-packages/nbclient/client.py", line 553, in async_execute
    await self.async_execute_cell(
  File "/Users/jankirenz/opt/anaconda3/lib/python3.8/site-packages/nbclient/client.py", line 857, in async_execute_cell
    self._check_raise_for_error(cell, exec_reply)
  File "/Users/jankirenz/opt/anaconda3/lib/python3.8/site-packages/nbclient/client.py", line 760, in _check_raise_for_error
    raise CellExecutionError.from_cell_and_msg(cell, exec_reply_content)
nbclient.exceptions.CellExecutionError: An error occurred while executing the following cell:
------------------
plt.semilogx(model.alphas_, model.mse_path_, ":")
plt.plot(
    model.alphas_ ,
    model.mse_path_.mean(axis=-1),
    "k",
    label="Average across the folds",
    linewidth=2,
)
plt.axvline(
    model.alpha_ + EPSILON, linestyle="--", color="k", label="alpha: CV estimate"
)

plt.legend()
plt.xlabel("alphas")
plt.ylabel("Mean square error")
plt.title("Mean square error on each fold")
plt.axis("tight")

ymin, ymax = 50000, 250000
plt.ylim(ymin, ymax);
------------------

[0;31m---------------------------------------------------------------------------[0m
[0;31mNameError[0m                                 Traceback (most recent call last)
[0;32m/var/folders/9c/_3s5jt3n60j__flsgl0t72340000gn/T/ipykernel_3420/1614548325.py[0m in [0;36m<module>[0;34m[0m
[1;32m      8[0m )
[1;32m      9[0m plt.axvline(
[0;32m---> 10[0;31m     [0mmodel[0m[0;34m.[0m[0malpha_[0m [0;34m+[0m [0mEPSILON[0m[0;34m,[0m [0mlinestyle[0m[0;34m=[0m[0;34m"--"[0m[0;34m,[0m [0mcolor[0m[0;34m=[0m[0;34m"k"[0m[0;34m,[0m [0mlabel[0m[0;34m=[0m[0;34m"alpha: CV estimate"[0m[0;34m[0m[0;34m[0m[0m
[0m[1;32m     11[0m )
[1;32m     12[0m [0;34m[0m[0m

[0;31mNameError[0m: name 'EPSILON' is not defined
NameError: name 'EPSILON' is not defined

