Traceback (most recent call last):
  File "/Users/jankirenz/opt/anaconda3/lib/python3.8/site-packages/jupyter_cache/executors/utils.py", line 51, in single_nb_execution
    executenb(
  File "/Users/jankirenz/opt/anaconda3/lib/python3.8/site-packages/nbclient/client.py", line 1112, in execute
    return NotebookClient(nb=nb, resources=resources, km=km, **kwargs).execute()
  File "/Users/jankirenz/opt/anaconda3/lib/python3.8/site-packages/nbclient/util.py", line 74, in wrapped
    return just_run(coro(*args, **kwargs))
  File "/Users/jankirenz/opt/anaconda3/lib/python3.8/site-packages/nbclient/util.py", line 53, in just_run
    return loop.run_until_complete(coro)
  File "/Users/jankirenz/opt/anaconda3/lib/python3.8/asyncio/base_events.py", line 616, in run_until_complete
    return future.result()
  File "/Users/jankirenz/opt/anaconda3/lib/python3.8/site-packages/nbclient/client.py", line 553, in async_execute
    await self.async_execute_cell(
  File "/Users/jankirenz/opt/anaconda3/lib/python3.8/site-packages/nbclient/client.py", line 857, in async_execute_cell
    self._check_raise_for_error(cell, exec_reply)
  File "/Users/jankirenz/opt/anaconda3/lib/python3.8/site-packages/nbclient/client.py", line 760, in _check_raise_for_error
    raise CellExecutionError.from_cell_and_msg(cell, exec_reply_content)
nbclient.exceptions.CellExecutionError: An error occurred while executing the following cell:
------------------
import numpy as np

# Create observations
xp = np.linspace(X_test.min(),X_test.max(), 100)
# Make some predictions
pred = cs.predict(dmatrix("bs(xp, knots=(25,40,60), include_intercept=False)", {"xp": xp}, return_type='dataframe'))

# plot
sns.scatterplot(x=X_train['age'], y=y_train['wage'])
plt.plot(xp, pred, label='Cubic spline with degree=3 (3 knots)')
plt.legend();
------------------

[0;31m---------------------------------------------------------------------------[0m
[0;31mNameError[0m                                 Traceback (most recent call last)
[0;32m/var/folders/9c/_3s5jt3n60j__flsgl0t72340000gn/T/ipykernel_10577/2021499229.py[0m in [0;36m<module>[0;34m[0m
[1;32m      8[0m [0;31m# plot[0m[0;34m[0m[0;34m[0m[0;34m[0m[0m
[1;32m      9[0m [0msns[0m[0;34m.[0m[0mscatterplot[0m[0;34m([0m[0mx[0m[0;34m=[0m[0mX_train[0m[0;34m[[0m[0;34m'age'[0m[0;34m][0m[0;34m,[0m [0my[0m[0;34m=[0m[0my_train[0m[0;34m[[0m[0;34m'wage'[0m[0;34m][0m[0;34m)[0m[0;34m[0m[0;34m[0m[0m
[0;32m---> 10[0;31m [0mplt[0m[0;34m.[0m[0mplot[0m[0;34m([0m[0mxp[0m[0;34m,[0m [0mpred[0m[0;34m,[0m [0mlabel[0m[0;34m=[0m[0;34m'Cubic spline with degree=3 (3 knots)'[0m[0;34m)[0m[0;34m[0m[0;34m[0m[0m
[0m[1;32m     11[0m [0mplt[0m[0;34m.[0m[0mlegend[0m[0;34m([0m[0;34m)[0m[0;34m;[0m[0;34m[0m[0;34m[0m[0m

[0;31mNameError[0m: name 'plt' is not defined
NameError: name 'plt' is not defined

