Traceback (most recent call last):
  File "/Users/jankirenz/opt/anaconda3/lib/python3.8/site-packages/jupyter_cache/executors/utils.py", line 51, in single_nb_execution
    executenb(
  File "/Users/jankirenz/opt/anaconda3/lib/python3.8/site-packages/nbclient/client.py", line 1112, in execute
    return NotebookClient(nb=nb, resources=resources, km=km, **kwargs).execute()
  File "/Users/jankirenz/opt/anaconda3/lib/python3.8/site-packages/nbclient/util.py", line 74, in wrapped
    return just_run(coro(*args, **kwargs))
  File "/Users/jankirenz/opt/anaconda3/lib/python3.8/site-packages/nbclient/util.py", line 53, in just_run
    return loop.run_until_complete(coro)
  File "/Users/jankirenz/opt/anaconda3/lib/python3.8/asyncio/base_events.py", line 616, in run_until_complete
    return future.result()
  File "/Users/jankirenz/opt/anaconda3/lib/python3.8/site-packages/nbclient/client.py", line 553, in async_execute
    await self.async_execute_cell(
  File "/Users/jankirenz/opt/anaconda3/lib/python3.8/site-packages/nbclient/client.py", line 857, in async_execute_cell
    self._check_raise_for_error(cell, exec_reply)
  File "/Users/jankirenz/opt/anaconda3/lib/python3.8/site-packages/nbclient/client.py", line 760, in _check_raise_for_error
    raise CellExecutionError.from_cell_and_msg(cell, exec_reply_content)
nbclient.exceptions.CellExecutionError: An error occurred while executing the following cell:
------------------
sm.stats.outliers_influence.variance_inflation_factor(exog, exog_idx)
------------------

[0;31m---------------------------------------------------------------------------[0m
[0;31mAttributeError[0m                            Traceback (most recent call last)
[0;32m/var/folders/9c/_3s5jt3n60j__flsgl0t72340000gn/T/ipykernel_4292/507250405.py[0m in [0;36m<module>[0;34m[0m
[0;32m----> 1[0;31m [0msm[0m[0;34m.[0m[0mstats[0m[0;34m.[0m[0moutliers_influence[0m[0;34m.[0m[0mvariance_inflation_factor[0m[0;34m([0m[0mexog[0m[0;34m,[0m [0mexog_idx[0m[0;34m)[0m[0;34m[0m[0;34m[0m[0m
[0m
[0;31mAttributeError[0m: module 'statsmodels.stats.api' has no attribute 'outliers_influence'
AttributeError: module 'statsmodels.stats.api' has no attribute 'outliers_influence'

